Workbook
Name dm_employment_status: 'DANH_MUC'!$A$4:INDEX('DANH_MUC'!$A:$A,MAX(4,COUNTA('DANH_MUC'!$A:$A)+1))
Name dm_gender: 'DANH_MUC'!$B$4:INDEX('DANH_MUC'!$B:$B,MAX(4,COUNTA('DANH_MUC'!$B:$B)+1))
Name dm_job_vi: 'DANH_MUC'!$C$4:INDEX('DANH_MUC'!$C:$C,MAX(4,COUNTA('DANH_MUC'!$C:$C)+1))
Name dm_job_en: 'DANH_MUC'!$D$4:INDEX('DANH_MUC'!$D:$D,MAX(4,COUNTA('DANH_MUC'!$D:$D)+1))
Name dm_department: 'DANH_MUC'!$E$4:INDEX('DANH_MUC'!$E:$E,MAX(4,COUNTA('DANH_MUC'!$E:$E)+1))
Name dm_team: 'DANH_MUC'!$F$4:INDEX('DANH_MUC'!$F:$F,MAX(4,COUNTA('DANH_MUC'!$F:$F)+1))
Name dm_branch: 'DANH_MUC'!$G$4:INDEX('DANH_MUC'!$G:$G,MAX(4,COUNTA('DANH_MUC'!$G:$G)+1))
Name dm_grade: 'DANH_MUC'!$H$4:INDEX('DANH_MUC'!$H:$H,MAX(4,COUNTA('DANH_MUC'!$H:$H)+1))
Name dm_level: 'DANH_MUC'!$I$4:INDEX('DANH_MUC'!$I:$I,MAX(4,COUNTA('DANH_MUC'!$I:$I)+1))

Sheet BAT_DAU
B2: HR DATA INPUT WIZARD
B4: Form chuẩn cho pipeline SharePoint ↔ HR App · Phiên bản 1.0
B6: Bước 1 | G6: Bước 2 | L6: Bước 3
B7: Nhập hồ sơ nhân sự | G7: Nhập thông tin công việc | L7: Kiểm tra chất lượng
B8: Mã, họ tên, liên hệ và thông tin cơ bản | G8: Phòng ban, chức danh, quản lý và lương | L8: Sửa toàn bộ lỗi trước khi đưa lên SharePoint
B13: QUY TẮC QUAN TRỌNG
B14: 1. Giữ Mã nhân viên dưới dạng text; mã 00001 không được đổi thành 1.
B15: 2. Chỉ nhập vào ô màu vàng nhạt. Ô xám là công thức kiểm tra và đã được khóa.
B16: 3. Dùng danh sách chọn cho trạng thái, giới tính, phòng ban, bộ phận, chức danh và chi nhánh.
B17: 4. Không xóa/đổi tên sheet, tiêu đề cột hoặc Excel Table; pipeline dùng các định danh này.
B18: 5. Chỉ đưa file lên SharePoint khi trang 03_KIEM_TRA hiển thị SẴN SÀNG.
B21: Danh mục có thể chỉnh tại sheet DANH_MUC. Các công thức kiểm tra chỉ nhằm đảm bảo chất lượng nhập liệu; quyền truy cập dữ liệu nhạy cảm vẫn do HR App và RLS kiểm soát.

Sheet 01_HO_SO
A1: BƯỚC 1 · HỒ SƠ NHÂN SỰ
A2: Nhập một dòng cho mỗi nhân viên. Ô vàng là vùng nhập; cột trạng thái/lỗi được tính tự động.
A5: Trạng thái kiểm tra | B5: Lỗi dữ liệu | C5: Mã nhân viên | D5: Họ và tên | E5: Ngày sinh | F5: Giới tính | G5: Email cá nhân | H5: Email công ty | I5: Số điện thoại | J5: Địa chỉ hiện tại | K5: Ghi chú
A6: =IF($C6="","CHƯA NHẬP",IF($B6="","HỢP LỆ","LỖI")) | B6: =IF($C6="","",TEXTJOIN(" | ",TRUE,IF($C6="","Thiếu mã nhân viên",""),IF(COUNTIF($C$6:$C$505,$C6)>1,"Trùng mã nhân viên",""),IF($D6="","Thiếu họ tên",""),IF(AND($E6<>"",OR(NOT(ISNUMBER($E6)),$E6<DATE(1940,1,1),$E6>TODAY())),"Ngày sinh không hợp lệ",""),IF(AND($G6<>"",OR(ISERROR(SEARCH("@",$G6)),ISERROR(SEARCH(".",$G6)))),"Email cá nhân không hợp lệ",""),IF(AND($H6<>"",OR(ISERROR(SEARCH("@",$H6)),ISERROR(SEARCH(".",$H6)))),"Email công ty không hợp lệ",""),IF(AND($I6<>"",OR(LEN($I6)<9,LEN($I6)>15,NOT(ISNUMBER(--$I6)))),"Số điện thoại không hợp lệ","")))
A7: =IF($C7="","CHƯA NHẬP",IF($B7="","HỢP LỆ","LỖI")) | B7: =IF($C7="","",TEXTJOIN(" | ",TRUE,IF($C7="","Thiếu mã nhân viên",""),IF(COUNTIF($C$6:$C$505,$C7)>1,"Trùng mã nhân viên",""),IF($D7="","Thiếu họ tên",""),IF(AND($E7<>"",OR(NOT(ISNUMBER($E7)),$E7<DATE(1940,1,1),$E7>TODAY())),"Ngày sinh không hợp lệ",""),IF(AND($G7<>"",OR(ISERROR(SEARCH("@",$G7)),ISERROR(SEARCH(".",$G7)))),"Email cá nhân không hợp lệ",""),IF(AND($H7<>"",OR(ISERROR(SEARCH("@",$H7)),ISERROR(SEARCH(".",$H7)))),"Email công ty không hợp lệ",""),IF(AND($I7<>"",OR(LEN($I7)<9,LEN($I7)>15,NOT(ISNUMBER(--$I7)))),"Số điện thoại không hợp lệ","")))
A8: =IF($C8="","CHƯA NHẬP",IF($B8="","HỢP LỆ","LỖI")) | B8: =IF($C8="","",TEXTJOIN(" | ",TRUE,IF($C8="","Thiếu mã nhân viên",""),IF(COUNTIF($C$6:$C$505,$C8)>1,"Trùng mã nhân viên",""),IF($D8="","Thiếu họ tên",""),IF(AND($E8<>"",OR(NOT(ISNUMBER($E8)),$E8<DATE(1940,1,1),$E8>TODAY())),"Ngày sinh không hợp lệ",""),IF(AND($G8<>"",OR(ISERROR(SEARCH("@",$G8)),ISERROR(SEARCH(".",$G8)))),"Email cá nhân không hợp lệ",""),IF(AND($H8<>"",OR(ISERROR(SEARCH("@",$H8)),ISERROR(SEARCH(".",$H8)))),"Email công ty không hợp lệ",""),IF(AND($I8<>"",OR(LEN($I8)<9,LEN($I8)>15,NOT(ISNUMBER(--$I8)))),"Số điện thoại không hợp lệ","")))
A9: =IF($C9="","CHƯA NHẬP",IF($B9="","HỢP LỆ","LỖI")) | B9: =IF($C9="","",TEXTJOIN(" | ",TRUE,IF($C9="","Thiếu mã nhân viên",""),IF(COUNTIF($C$6:$C$505,$C9)>1,"Trùng mã nhân viên",""),IF($D9="","Thiếu họ tên",""),IF(AND($E9<>"",OR(NOT(ISNUMBER($E9)),$E9<DATE(1940,1,1),$E9>TODAY())),"Ngày sinh không hợp lệ",""),IF(AND($G9<>"",OR(ISERROR(SEARCH("@",$G9)),ISERROR(SEARCH(".",$G9)))),"Email cá nhân không hợp lệ",""),IF(AND($H9<>"",OR(ISERROR(SEARCH("@",$H9)),ISERROR(SEARCH(".",$H9)))),"Email công ty không hợp lệ",""),IF(AND($I9<>"",OR(LEN($I9)<9,LEN($I9)>15,NOT(ISNUMBER(--$I9)))),"Số điện thoại không hợp lệ","")))
A10: =IF($C10="","CHƯA NHẬP",IF($B10="","HỢP LỆ","LỖI")) | B10: =IF($C10="","",TEXTJOIN(" | ",TRUE,IF($C10="","Thiếu mã nhân viên",""),IF(COUNTIF($C$6:$C$505,$C10)>1,"Trùng mã nhân viên",""),IF($D10="","Thiếu họ tên",""),IF(AND($E10<>"",OR(NOT(ISNUMBER($E10)),$E10<DATE(1940,1,1),$E10>TODAY())),"Ngày sinh không hợp lệ",""),IF(AND($G10<>"",OR(ISERROR(SEARCH("@",$G10)),ISERROR(SEARCH(".",$G10)))),"Email cá nhân không hợp lệ",""),IF(AND($H10<>"",OR(ISERROR(SEARCH("@",$H10)),ISERROR(SEARCH(".",$H10)))),"Email công ty không hợp lệ",""),IF(AND($I10<>"",OR(LEN($I10)<9,LEN($I10)>15,NOT(ISNUMBER(--$I10)))),"Số điện thoại không hợp lệ","")))
A11: =IF($C11="","CHƯA NHẬP",IF($B11="","HỢP LỆ","LỖI")) | B11: =IF($C11="","",TEXTJOIN(" | ",TRUE,IF($C11="","Thiếu mã nhân viên",""),IF(COUNTIF($C$6:$C$505,$C11)>1,"Trùng mã nhân viên",""),IF($D11="","Thiếu họ tên",""),IF(AND($E11<>"",OR(NOT(ISNUMBER($E11)),$E11<DATE(1940,1,1),$E11>TODAY())),"Ngày sinh không hợp lệ",""),IF(AND($G11<>"",OR(ISERROR(SEARCH("@",$G11)),ISERROR(SEARCH(".",$G11)))),"Email cá nhân không hợp lệ",""),IF(AND($H11<>"",OR(ISERROR(SEARCH("@",$H11)),ISERROR(SEARCH(".",$H11)))),"Email công ty không hợp lệ",""),IF(AND($I11<>"",OR(LEN($I11)<9,LEN($I11)>15,NOT(ISNUMBER(--$I11)))),"Số điện thoại không hợp lệ","")))
A12: =IF($C12="","CHƯA NHẬP",IF($B12="","HỢP LỆ","LỖI")) | B12: =IF($C12="","",TEXTJOIN(" | ",TRUE,IF($C12="","Thiếu mã nhân viên",""),IF(COUNTIF($C$6:$C$505,$C12)>1,"Trùng mã nhân viên",""),IF($D12="","Thiếu họ tên",""),IF(AND($E12<>"",OR(NOT(ISNUMBER($E12)),$E12<DATE(1940,1,1),$E12>TODAY())),"Ngày sinh không hợp lệ",""),IF(AND($G12<>"",OR(ISERROR(SEARCH("@",$G12)),ISERROR(SEARCH(".",$G12)))),"Email cá nhân không hợp lệ",""),IF(AND($H12<>"",OR(ISERROR(SEARCH("@",$H12)),ISERROR(SEARCH(".",$H12)))),"Email công ty không hợp lệ",""),IF(AND($I12<>"",OR(LEN($I12)<9,LEN($I12)>15,NOT(ISNUMBER(--$I12)))),"Số điện thoại không hợp lệ","")))
A13: =IF($C13="","CHƯA NHẬP",IF($B13="","HỢP LỆ","LỖI")) | B13: =IF($C13="","",TEXTJOIN(" | ",TRUE,IF($C13="","Thiếu mã nhân viên",""),IF(COUNTIF($C$6:$C$505,$C13)>1,"Trùng mã nhân viên",""),IF($D13="","Thiếu họ tên",""),IF(AND($E13<>"",OR(NOT(ISNUMBER($E13)),$E13<DATE(1940,1,1),$E13>TODAY())),"Ngày sinh không hợp lệ",""),IF(AND($G13<>"",OR(ISERROR(SEARCH("@",$G13)),ISERROR(SEARCH(".",$G13)))),"Email cá nhân không hợp lệ",""),IF(AND($H13<>"",OR(ISERROR(SEARCH("@",$H13)),ISERROR(SEARCH(".",$H13)))),"Email công ty không hợp lệ",""),IF(AND($I13<>"",OR(LEN($I13)<9,LEN($I13)>15,NOT(ISNUMBER(--$I13)))),"Số điện thoại không hợp lệ","")))
A14: =IF($C14="","CHƯA NHẬP",IF($B14="","HỢP LỆ","LỖI")) | B14: =IF($C14="","",TEXTJOIN(" | ",TRUE,IF($C14="","Thiếu mã nhân viên",""),IF(COUNTIF($C$6:$C$505,$C14)>1,"Trùng mã nhân viên",""),IF($D14="","Thiếu họ tên",""),IF(AND($E14<>"",OR(NOT(ISNUMBER($E14)),$E14<DATE(1940,1,1),$E14>TODAY())),"Ngày sinh không hợp lệ",""),IF(AND($G14<>"",OR(ISERROR(SEARCH("@",$G14)),ISERROR(SEARCH(".",$G14)))),"Email cá nhân không hợp lệ",""),IF(AND($H14<>"",OR(ISERROR(SEARCH("@",$H14)),ISERROR(SEARCH(".",$H14)))),"Email công ty không hợp lệ",""),IF(AND($I14<>"",OR(LEN($I14)<9,LEN($I14)>15,NOT(ISNUMBER(--$I14)))),"Số điện thoại không hợp lệ","")))
A15: =IF($C15="","CHƯA NHẬP",IF($B15="","HỢP LỆ","LỖI")) | B15: =IF($C15="","",TEXTJOIN(" | ",TRUE,IF($C15="","Thiếu mã nhân viên",""),IF(COUNTIF($C$6:$C$505,$C15)>1,"Trùng mã nhân viên",""),IF($D15="","Thiếu họ tên",""),IF(AND($E15<>"",OR(NOT(ISNUMBER($E15)),$E15<DATE(1940,1,1),$E15>TODAY())),"Ngày sinh không hợp lệ",""),IF(AND($G15<>"",OR(ISERROR(SEARCH("@",$G15)),ISERROR(SEARCH(".",$G15)))),"Email cá nhân không hợp lệ",""),IF(AND($H15<>"",OR(ISERROR(SEARCH("@",$H15)),ISERROR(SEARCH(".",$H15)))),"Email công ty không hợp lệ",""),IF(AND($I15<>"",OR(LEN($I15)<9,LEN($I15)>15,NOT(ISNUMBER(--$I15)))),"Số điện thoại không hợp lệ","")))
A16: =IF($C16="","CHƯA NHẬP",IF($B16="","HỢP LỆ","LỖI")) | B16: =IF($C16="","",TEXTJOIN(" | ",TRUE,IF($C16="","Thiếu mã nhân viên",""),IF(COUNTIF($C$6:$C$505,$C16)>1,"Trùng mã nhân viên",""),IF($D16="","Thiếu họ tên",""),IF(AND($E16<>"",OR(NOT(ISNUMBER($E16)),$E16<DATE(1940,1,1),$E16>TODAY())),"Ngày sinh không hợp lệ",""),IF(AND($G16<>"",OR(ISERROR(SEARCH("@",$G16)),ISERROR(SEARCH(".",$G16)))),"Email cá nhân không hợp lệ",""),IF(AND($H16<>"",OR(ISERROR(SEARCH("@",$H16)),ISERROR(SEARCH(".",$H16)))),"Email công ty không hợp lệ",""),IF(AND($I16<>"",OR(LEN($I16)<9,LEN($I16)>15,NOT(ISNUMBER(--$I16)))),"Số điện thoại không hợp lệ","")))
A17: =IF($C17="","CHƯA NHẬP",IF($B17="","HỢP LỆ","LỖI")) | B17: =IF($C17="","",TEXTJOIN(" | ",TRUE,IF($C17="","Thiếu mã nhân viên",""),IF(COUNTIF($C$6:$C$505,$C17)>1,"Trùng mã nhân viên",""),IF($D17="","Thiếu họ tên",""),IF(AND($E17<>"",OR(NOT(ISNUMBER($E17)),$E17<DATE(1940,1,1),$E17>TODAY())),"Ngày sinh không hợp lệ",""),IF(AND($G17<>"",OR(ISERROR(SEARCH("@",$G17)),ISERROR(SEARCH(".",$G17)))),"Email cá nhân không hợp lệ",""),IF(AND($H17<>"",OR(ISERROR(SEARCH("@",$H17)),ISERROR(SEARCH(".",$H17)))),"Email công ty không hợp lệ",""),IF(AND($I17<>"",OR(LEN($I17)<9,LEN($I17)>15,NOT(ISNUMBER(--$I17)))),"Số điện thoại không hợp lệ","")))
... A505: =IF($C505="","CHƯA NHẬP",IF($B505="","HỢP LỆ","LỖI")) | B505: =IF($C505="","",TEXTJOIN(" | ",TRUE,IF($C505="","Thiếu mã nhân viên",""),IF(COUNTIF($C$6:$C$505,$C505)>1,"Trùng mã nhân viên",""),IF($D505="","Thiếu họ tên",""),IF(AND($E505<>"",OR(NOT(ISNUMBER($E505)),$E505<DATE(1940,1,1),$E505>TODAY())),"Ngày sinh không hợp lệ",""),IF(AND($G505<>"",OR(ISERROR(SEARCH("@",$G505)),ISERROR(SEARCH(".",$G505)))),"Email cá nhân không hợp lệ",""),IF(AND($H505<>"",OR(ISERROR(SEARCH("@",$H505)),ISERROR(SEARCH(".",$H505)))),"Email công ty không hợp lệ",""),IF(AND($I505<>"",OR(LEN($I505)<9,LEN($I505)>15,NOT(ISNUMBER(--$I505)))),"Số điện thoại không hợp lệ","")))

Sheet 02_CONG_VIEC
A1: BƯỚC 2 · THÔNG TIN CÔNG VIỆC
A2: Mã nhân viên phải tồn tại ở Bước 1. Dữ liệu phòng ban/chức danh lấy từ danh mục và có thể mở rộng.
A5: Trạng thái kiểm tra | B5: Lỗi dữ liệu | C5: Mã nhân viên | D5: Trạng thái làm việc | E5: Ngày vào công ty | F5: Chi nhánh | G5: Phòng ban | H5: Bộ phận | I5: Chức danh (VI) | J5: Position (EN) | K5: Ngạch | L5: Cấp bậc | M5: Mã quản lý trực tiếp | N5: Lương cơ bản | O5: Ghi chú
A6: =IF($C6="","CHƯA NHẬP",IF($B6="","HỢP LỆ","LỖI")) | B6: =IF($C6="","",TEXTJOIN(" | ",TRUE,IF(COUNTIF('01_HO_SO'!$C$6:$C$505,$C6)=0,"Mã chưa có ở Bước 1",""),IF(COUNTIF($C$6:$C$505,$C6)>1,"Trùng mã trong thông tin công việc",""),IF($D6="","Thiếu trạng thái làm việc",""),IF($E6="","Thiếu ngày vào công ty",IF(OR(NOT(ISNUMBER($E6)),$E6>TODAY()),"Ngày vào công ty không hợp lệ","")),IF($G6="","Thiếu phòng ban",""),IF($I6="","Thiếu chức danh",""),IF(AND($M6<>"",COUNTIF('01_HO_SO'!$C$6:$C$505,$M6)=0),"Mã quản lý không tồn tại",""),IF(AND($M6<>"",$M6=$C6),"Không thể tự quản lý chính mình",""),IF(OR($N6<0,$N6>1000000000),"Lương cơ bản ngoài phạm vi",""))) | J6: =IF($I6="","",IFERROR(INDEX(DANH_MUC!$D$4:$D$1000,MATCH($I6,DANH_MUC!$C$4:$C$1000,0)),""))
A7: =IF($C7="","CHƯA NHẬP",IF($B7="","HỢP LỆ","LỖI")) | B7: =IF($C7="","",TEXTJOIN(" | ",TRUE,IF(COUNTIF('01_HO_SO'!$C$6:$C$505,$C7)=0,"Mã chưa có ở Bước 1",""),IF(COUNTIF($C$6:$C$505,$C7)>1,"Trùng mã trong thông tin công việc",""),IF($D7="","Thiếu trạng thái làm việc",""),IF($E7="","Thiếu ngày vào công ty",IF(OR(NOT(ISNUMBER($E7)),$E7>TODAY()),"Ngày vào công ty không hợp lệ","")),IF($G7="","Thiếu phòng ban",""),IF($I7="","Thiếu chức danh",""),IF(AND($M7<>"",COUNTIF('01_HO_SO'!$C$6:$C$505,$M7)=0),"Mã quản lý không tồn tại",""),IF(AND($M7<>"",$M7=$C7),"Không thể tự quản lý chính mình",""),IF(OR($N7<0,$N7>1000000000),"Lương cơ bản ngoài phạm vi",""))) | J7: =IF($I7="","",IFERROR(INDEX(DANH_MUC!$D$4:$D$1000,MATCH($I7,DANH_MUC!$C$4:$C$1000,0)),""))
A8: =IF($C8="","CHƯA NHẬP",IF($B8="","HỢP LỆ","LỖI")) | B8: =IF($C8="","",TEXTJOIN(" | ",TRUE,IF(COUNTIF('01_HO_SO'!$C$6:$C$505,$C8)=0,"Mã chưa có ở Bước 1",""),IF(COUNTIF($C$6:$C$505,$C8)>1,"Trùng mã trong thông tin công việc",""),IF($D8="","Thiếu trạng thái làm việc",""),IF($E8="","Thiếu ngày vào công ty",IF(OR(NOT(ISNUMBER($E8)),$E8>TODAY()),"Ngày vào công ty không hợp lệ","")),IF($G8="","Thiếu phòng ban",""),IF($I8="","Thiếu chức danh",""),IF(AND($M8<>"",COUNTIF('01_HO_SO'!$C$6:$C$505,$M8)=0),"Mã quản lý không tồn tại",""),IF(AND($M8<>"",$M8=$C8),"Không thể tự quản lý chính mình",""),IF(OR($N8<0,$N8>1000000000),"Lương cơ bản ngoài phạm vi",""))) | J8: =IF($I8="","",IFERROR(INDEX(DANH_MUC!$D$4:$D$1000,MATCH($I8,DANH_MUC!$C$4:$C$1000,0)),""))
A9: =IF($C9="","CHƯA NHẬP",IF($B9="","HỢP LỆ","LỖI")) | B9: =IF($C9="","",TEXTJOIN(" | ",TRUE,IF(COUNTIF('01_HO_SO'!$C$6:$C$505,$C9)=0,"Mã chưa có ở Bước 1",""),IF(COUNTIF($C$6:$C$505,$C9)>1,"Trùng mã trong thông tin công việc",""),IF($D9="","Thiếu trạng thái làm việc",""),IF($E9="","Thiếu ngày vào công ty",IF(OR(NOT(ISNUMBER($E9)),$E9>TODAY()),"Ngày vào công ty không hợp lệ","")),IF($G9="","Thiếu phòng ban",""),IF($I9="","Thiếu chức danh",""),IF(AND($M9<>"",COUNTIF('01_HO_SO'!$C$6:$C$505,$M9)=0),"Mã quản lý không tồn tại",""),IF(AND($M9<>"",$M9=$C9),"Không thể tự quản lý chính mình",""),IF(OR($N9<0,$N9>1000000000),"Lương cơ bản ngoài phạm vi",""))) | J9: =IF($I9="","",IFERROR(INDEX(DANH_MUC!$D$4:$D$1000,MATCH($I9,DANH_MUC!$C$4:$C$1000,0)),""))
A10: =IF($C10="","CHƯA NHẬP",IF($B10="","HỢP LỆ","LỖI")) | B10: =IF($C10="","",TEXTJOIN(" | ",TRUE,IF(COUNTIF('01_HO_SO'!$C$6:$C$505,$C10)=0,"Mã chưa có ở Bước 1",""),IF(COUNTIF($C$6:$C$505,$C10)>1,"Trùng mã trong thông tin công việc",""),IF($D10="","Thiếu trạng thái làm việc",""),IF($E10="","Thiếu ngày vào công ty",IF(OR(NOT(ISNUMBER($E10)),$E10>TODAY()),"Ngày vào công ty không hợp lệ","")),IF($G10="","Thiếu phòng ban",""),IF($I10="","Thiếu chức danh",""),IF(AND($M10<>"",COUNTIF('01_HO_SO'!$C$6:$C$505,$M10)=0),"Mã quản lý không tồn tại",""),IF(AND($M10<>"",$M10=$C10),"Không thể tự quản lý chính mình",""),IF(OR($N10<0,$N10>1000000000),"Lương cơ bản ngoài phạm vi",""))) | J10: =IF($I10="","",IFERROR(INDEX(DANH_MUC!$D$4:$D$1000,MATCH($I10,DANH_MUC!$C$4:$C$1000,0)),""))
A11: =IF($C11="","CHƯA NHẬP",IF($B11="","HỢP LỆ","LỖI")) | B11: =IF($C11="","",TEXTJOIN(" | ",TRUE,IF(COUNTIF('01_HO_SO'!$C$6:$C$505,$C11)=0,"Mã chưa có ở Bước 1",""),IF(COUNTIF($C$6:$C$505,$C11)>1,"Trùng mã trong thông tin công việc",""),IF($D11="","Thiếu trạng thái làm việc",""),IF($E11="","Thiếu ngày vào công ty",IF(OR(NOT(ISNUMBER($E11)),$E11>TODAY()),"Ngày vào công ty không hợp lệ","")),IF($G11="","Thiếu phòng ban",""),IF($I11="","Thiếu chức danh",""),IF(AND($M11<>"",COUNTIF('01_HO_SO'!$C$6:$C$505,$M11)=0),"Mã quản lý không tồn tại",""),IF(AND($M11<>"",$M11=$C11),"Không thể tự quản lý chính mình",""),IF(OR($N11<0,$N11>1000000000),"Lương cơ bản ngoài phạm vi",""))) | J11: =IF($I11="","",IFERROR(INDEX(DANH_MUC!$D$4:$D$1000,MATCH($I11,DANH_MUC!$C$4:$C$1000,0)),""))
A12: =IF($C12="","CHƯA NHẬP",IF($B12="","HỢP LỆ","LỖI")) | B12: =IF($C12="","",TEXTJOIN(" | ",TRUE,IF(COUNTIF('01_HO_SO'!$C$6:$C$505,$C12)=0,"Mã chưa có ở Bước 1",""),IF(COUNTIF($C$6:$C$505,$C12)>1,"Trùng mã trong thông tin công việc",""),IF($D12="","Thiếu trạng thái làm việc",""),IF($E12="","Thiếu ngày vào công ty",IF(OR(NOT(ISNUMBER($E12)),$E12>TODAY()),"Ngày vào công ty không hợp lệ","")),IF($G12="","Thiếu phòng ban",""),IF($I12="","Thiếu chức danh",""),IF(AND($M12<>"",COUNTIF('01_HO_SO'!$C$6:$C$505,$M12)=0),"Mã quản lý không tồn tại",""),IF(AND($M12<>"",$M12=$C12),"Không thể tự quản lý chính mình",""),IF(OR($N12<0,$N12>1000000000),"Lương cơ bản ngoài phạm vi",""))) | J12: =IF($I12="","",IFERROR(INDEX(DANH_MUC!$D$4:$D$1000,MATCH($I12,DANH_MUC!$C$4:$C$1000,0)),""))
A13: =IF($C13="","CHƯA NHẬP",IF($B13="","HỢP LỆ","LỖI")) | B13: =IF($C13="","",TEXTJOIN(" | ",TRUE,IF(COUNTIF('01_HO_SO'!$C$6:$C$505,$C13)=0,"Mã chưa có ở Bước 1",""),IF(COUNTIF($C$6:$C$505,$C13)>1,"Trùng mã trong thông tin công việc",""),IF($D13="","Thiếu trạng thái làm việc",""),IF($E13="","Thiếu ngày vào công ty",IF(OR(NOT(ISNUMBER($E13)),$E13>TODAY()),"Ngày vào công ty không hợp lệ","")),IF($G13="","Thiếu phòng ban",""),IF($I13="","Thiếu chức danh",""),IF(AND($M13<>"",COUNTIF('01_HO_SO'!$C$6:$C$505,$M13)=0),"Mã quản lý không tồn tại",""),IF(AND($M13<>"",$M13=$C13),"Không thể tự quản lý chính mình",""),IF(OR($N13<0,$N13>1000000000),"Lương cơ bản ngoài phạm vi",""))) | J13: =IF($I13="","",IFERROR(INDEX(DANH_MUC!$D$4:$D$1000,MATCH($I13,DANH_MUC!$C$4:$C$1000,0)),""))
A14: =IF($C14="","CHƯA NHẬP",IF($B14="","HỢP LỆ","LỖI")) | B14: =IF($C14="","",TEXTJOIN(" | ",TRUE,IF(COUNTIF('01_HO_SO'!$C$6:$C$505,$C14)=0,"Mã chưa có ở Bước 1",""),IF(COUNTIF($C$6:$C$505,$C14)>1,"Trùng mã trong thông tin công việc",""),IF($D14="","Thiếu trạng thái làm việc",""),IF($E14="","Thiếu ngày vào công ty",IF(OR(NOT(ISNUMBER($E14)),$E14>TODAY()),"Ngày vào công ty không hợp lệ","")),IF($G14="","Thiếu phòng ban",""),IF($I14="","Thiếu chức danh",""),IF(AND($M14<>"",COUNTIF('01_HO_SO'!$C$6:$C$505,$M14)=0),"Mã quản lý không tồn tại",""),IF(AND($M14<>"",$M14=$C14),"Không thể tự quản lý chính mình",""),IF(OR($N14<0,$N14>1000000000),"Lương cơ bản ngoài phạm vi",""))) | J14: =IF($I14="","",IFERROR(INDEX(DANH_MUC!$D$4:$D$1000,MATCH($I14,DANH_MUC!$C$4:$C$1000,0)),""))
A15: =IF($C15="","CHƯA NHẬP",IF($B15="","HỢP LỆ","LỖI")) | B15: =IF($C15="","",TEXTJOIN(" | ",TRUE,IF(COUNTIF('01_HO_SO'!$C$6:$C$505,$C15)=0,"Mã chưa có ở Bước 1",""),IF(COUNTIF($C$6:$C$505,$C15)>1,"Trùng mã trong thông tin công việc",""),IF($D15="","Thiếu trạng thái làm việc",""),IF($E15="","Thiếu ngày vào công ty",IF(OR(NOT(ISNUMBER($E15)),$E15>TODAY()),"Ngày vào công ty không hợp lệ","")),IF($G15="","Thiếu phòng ban",""),IF($I15="","Thiếu chức danh",""),IF(AND($M15<>"",COUNTIF('01_HO_SO'!$C$6:$C$505,$M15)=0),"Mã quản lý không tồn tại",""),IF(AND($M15<>"",$M15=$C15),"Không thể tự quản lý chính mình",""),IF(OR($N15<0,$N15>1000000000),"Lương cơ bản ngoài phạm vi",""))) | J15: =IF($I15="","",IFERROR(INDEX(DANH_MUC!$D$4:$D$1000,MATCH($I15,DANH_MUC!$C$4:$C$1000,0)),""))
A16: =IF($C16="","CHƯA NHẬP",IF($B16="","HỢP LỆ","LỖI")) | B16: =IF($C16="","",TEXTJOIN(" | ",TRUE,IF(COUNTIF('01_HO_SO'!$C$6:$C$505,$C16)=0,"Mã chưa có ở Bước 1",""),IF(COUNTIF($C$6:$C$505,$C16)>1,"Trùng mã trong thông tin công việc",""),IF($D16="","Thiếu trạng thái làm việc",""),IF($E16="","Thiếu ngày vào công ty",IF(OR(NOT(ISNUMBER($E16)),$E16>TODAY()),"Ngày vào công ty không hợp lệ","")),IF($G16="","Thiếu phòng ban",""),IF($I16="","Thiếu chức danh",""),IF(AND($M16<>"",COUNTIF('01_HO_SO'!$C$6:$C$505,$M16)=0),"Mã quản lý không tồn tại",""),IF(AND($M16<>"",$M16=$C16),"Không thể tự quản lý chính mình",""),IF(OR($N16<0,$N16>1000000000),"Lương cơ bản ngoài phạm vi",""))) | J16: =IF($I16="","",IFERROR(INDEX(DANH_MUC!$D$4:$D$1000,MATCH($I16,DANH_MUC!$C$4:$C$1000,0)),""))
A17: =IF($C17="","CHƯA NHẬP",IF($B17="","HỢP LỆ","LỖI")) | B17: =IF($C17="","",TEXTJOIN(" | ",TRUE,IF(COUNTIF('01_HO_SO'!$C$6:$C$505,$C17)=0,"Mã chưa có ở Bước 1",""),IF(COUNTIF($C$6:$C$505,$C17)>1,"Trùng mã trong thông tin công việc",""),IF($D17="","Thiếu trạng thái làm việc",""),IF($E17="","Thiếu ngày vào công ty",IF(OR(NOT(ISNUMBER($E17)),$E17>TODAY()),"Ngày vào công ty không hợp lệ","")),IF($G17="","Thiếu phòng ban",""),IF($I17="","Thiếu chức danh",""),IF(AND($M17<>"",COUNTIF('01_HO_SO'!$C$6:$C$505,$M17)=0),"Mã quản lý không tồn tại",""),IF(AND($M17<>"",$M17=$C17),"Không thể tự quản lý chính mình",""),IF(OR($N17<0,$N17>1000000000),"Lương cơ bản ngoài phạm vi",""))) | J17: =IF($I17="","",IFERROR(INDEX(DANH_MUC!$D$4:$D$1000,MATCH($I17,DANH_MUC!$C$4:$C$1000,0)),""))
... A505: =IF($C505="","CHƯA NHẬP",IF($B505="","HỢP LỆ","LỖI")) | B505: =IF($C505="","",TEXTJOIN(" | ",TRUE,IF(COUNTIF('01_HO_SO'!$C$6:$C$505,$C505)=0,"Mã chưa có ở Bước 1",""),IF(COUNTIF($C$6:$C$505,$C505)>1,"Trùng mã trong thông tin công việc",""),IF($D505="","Thiếu trạng thái làm việc",""),IF($E505="","Thiếu ngày vào công ty",IF(OR(NOT(ISNUMBER($E505)),$E505>TODAY()),"Ngày vào công ty không hợp lệ","")),IF($G505="","Thiếu phòng ban",""),IF($I505="","Thiếu chức danh",""),IF(AND($M505<>"",COUNTIF('01_HO_SO'!$C$6:$C$505,$M505)=0),"Mã quản lý không tồn tại",""),IF(AND($M505<>"",$M505=$C505),"Không thể tự quản lý chính mình",""),IF(OR($N505<0,$N505>1000000000),"Lương cơ bản ngoài phạm vi",""))) | J505: =IF($I505="","",IFERROR(INDEX(DANH_MUC!$D$4:$D$1000,MATCH($I505,DANH_MUC!$C$4:$C$1000,0)),""))

Sheet 03_KIEM_TRA
A1: BƯỚC 3 · KIỂM TRA CHẤT LƯỢNG
A2: Chỉ xuất/đưa lên SharePoint khi toàn bộ dữ liệu đang nhập hiển thị hợp lệ.
B5: Chỉ số | C5: Hồ sơ | D5: Công việc
B6: Tổng dòng đã nhập | C6: =COUNTIF('01_HO_SO'!$C$6:$C$505,"<>") | D6: =COUNTIF('02_CONG_VIEC'!$C$6:$C$505,"<>")
B7: Dòng hợp lệ | C7: =COUNTIF('01_HO_SO'!$A$6:$A$505,"HỢP LỆ") | D7: =COUNTIF('02_CONG_VIEC'!$A$6:$A$505,"HỢP LỆ")
B8: Dòng có lỗi | C8: =COUNTIF('01_HO_SO'!$A$6:$A$505,"LỖI") | D8: =COUNTIF('02_CONG_VIEC'!$A$6:$A$505,"LỖI")
B9: Mã trùng | C9: =COUNTIF('01_HO_SO'!$B$6:$B$505,"*Trùng mã*") | D9: =COUNTIF('02_CONG_VIEC'!$B$6:$B$505,"*Trùng mã*")
B10: Thiếu trường bắt buộc | C10: =COUNTIF('01_HO_SO'!$B$6:$B$505,"*Thiếu*") | D10: =COUNTIF('02_CONG_VIEC'!$B$6:$B$505,"*Thiếu*")
B13: =IF(AND(C8=0,D8=0,C6>0,C6=D6),"SẴN SÀNG ĐƯA LÊN SHAREPOINT","CHƯA SẴN SÀNG · HÃY SỬA LỖI")
B16: Tiêu chí sẵn sàng: có ít nhất 1 hồ sơ, số hồ sơ bằng số dòng công việc, và cả hai bước không còn dòng LỖI. Bộ kiểm tra trên HR App vẫn chạy lại trước khi ghi dữ liệu.
B20: Quay lại Bước 1 | C20: Quay lại Bước 2

Sheet DANH_MUC
A1: DANH MỤC CẤU HÌNH
A2: Người quản trị có thể bổ sung giá trị ở cuối từng cột. Không sắp xếp riêng cột Chức danh VI/EN vì đây là một cặp mapping.
A3: Trạng thái làm việc | B3: Giới tính | C3: Chức danh (VI) | D3: Position (EN) | E3: Phòng ban | F3: Bộ phận | G3: Chi nhánh | H3: Ngạch | I3: Cấp bậc
A4: Đang làm việc | B4: Nam | C4: Tổng giám đốc | D4: Chief Executive Officer (CEO) | E4: Hanoi Warehouse | F4: Chuyên viên cấp cao? Expert? | G4: 1 | H4: Warehouse Administrator | I4: Lãnh đạo
A5: Thử việc | B5: Nữ | C5: Chủ tịch HĐQT | D5: Chairman of the Board | E5: Offline Retail | F5: Senior Manager | G5: 2.1 | H5: Retail Area Sales Manager | I5: ??
A6: Tạm nghỉ | B6: Khác | C6: Phó giám đốc | D6: Deputy Director | E6: Executive Management | F6: Chuyên gia (làm việc độc lập) | G6: 8 | H6: Chairman of the Board
A7: Đã nghỉ việc | B7: Không công bố | C7: TNH bóng bàn | D7: Category Manager – Table Tennis | E7: Human Resources | F7: hay 5.1??? | G7: 2.2 | H7: Learning & Development Specialist
C8: TNH bóng chuyền | D8: Category Manager – Volleyball | E8: E-commerce | F8: Chuyên viên II | G8: 5.1 | H8: Omnichannel Coordinator
C9: Chuyên viên XNK | D9: Import-Export Specialist | E9: IT | F9: Senior Team Lead | G9: 5 | H9: Business Intelligence Analyst
C10: Trưởng phòng TCKT | D10: Head of Finance & Accounting | E10: Procurement | F10: Sai cấp bậc | G10: 3.1 | H10: Sales Operations Specialist
C11: Nhân viên kế toán | D11: Accountant | E11: Content | F11: Hay 5.2?? Quản trị 2 Phòng ban / Khối | G11: 5.2 | H11: Affiliate Growth Specialist
C12: Kế toán tổng hợp | D12: General Accountant | E12: Media Production | F12: Hay là 4.1? | G12: 4 | H12: Customer Growth & Experience Specialist
C13: Kế toán thuế | D13: Tax Accountant | E13: Customer Service | F13: Dưới 3.2 - Thương | G13: 7.2 | H13: E-commerce Marketplace Growth & Operations Specialist
C14: Mua hàng quốc tế | D14: International Purchasing | E14: Miếu Đầm Store | F14: 3.1 ? Bằng Ngô Bình Phương hay bằng Thương (ko quản lý nhân viên trực tiếp --> Chuyên viên cấp cao II) | G14: HCM | H14: Import–Export Specialist
C15: Nhân viên mua hàng | D15: Purchasing Executive | E15: Ho Chi Minh City Warehouse | F15: Hay là 2.2 ??? = Loan và Duyên | G15: HN | H15: Content Specialist
C16: Nhân viên PR, sự kiện | D16: PR & Events Executive | E16: Product Development | F16: hay là 3.1?? | H16: Content Creator
C17: Nhân viên thiết kế | D17: Designer | E17: Sales | F17: hay là 3.2??? Trưởng nhóm cấp cao | H17: E-commerce Content Creator
C18: Nhân viên Graphic Design | D18: Graphic Designer | E18: Administration | F18: Hay là 4.1 hay 5.1 ở level Chuyên gia | H18: Creative Lead
C19: Nhân viên PR (Tài trợ và sự kiện) | D19: PR Executive (Sponsorship & Events) | E19: Category Management | H19: Customer Service Specialist
C20: Trưởng bộ phận cung ứng | D20: Head of Supply Chain / Procurement | E20: Accounting | H20: Store Manager
C21: Trưởng bộ phận kho | D21: Head of Warehouse | E21: Quality Control | H21: Warehouse Coordinator
C22: Admin kho | D22: Warehouse Admin | E22: International Market Development | H22: Digital Performance Executive
C23: Lái xe | D23: Driver | E23: District 1 Store | H23: Footwear Product Development Manager
C24: Nhân viên kho | D24: Warehouse Staff | E24: District 2 Store | H24: B2B Sales Director
C25: Nhân viên in ép | D25: Heat Press / Printing Operator | E25: Graphic Design | H25: Creative Director
C26: Nhân viên mua hàng kiêm admin | D26: Purchasing & Admin Executive | E26: Apparel Projects | H26: General Administration Associate
C27: Nhân viên QC | D27: QC Staff | E27: Production Planning | H27: Head of Human Resources
C28: Chuyên viên SO | D28: Sales Order (SO) Specialist | E28: Partnerships, Advertising & Events | H28: Head of Product & Category Strategy
C29: Nhân viên IT Admin | D29: IT Admin | E29: Sales Administration | H29: Head of Product Design
C30: Sale Admin | D30: Sales Admin | E30: Design | H30: Livestream Host
... C33: TP.NSHC | D33: Head of HR & Admin | E33: Volleyball Category | H33: General Accountant
C34: Nhân sự tổng hợp | D34: HR Generalist | H34: Livestream Technical Operator
C35: Trưởng nhóm hành chính | D35: Admin Team Leader | H35: Product Technician
C36: Shipper | D36: Shipper | H36: Driver
C37: Tổ trưởng lái xe | D37: Driver Team Leader | H37: Executive Driver
C38: Nhân viên bảo vệ | D38: Security Guard | H38: Truck Driver
C39: Trưởng nhóm kinh doanh miền bắc | D39: Sales Team Leader – North | H39: International Marketing Specialist
C40: Nhân viên kinh doanh | D40: Sales Executive | H40: International Procurement Specialist
C41: Mua hàng tiếng Trung | D41: Chinese-language Purchasing (China Sourcing) | H41: Chinese-speaking Procurement Specialist
C42: Giám đốc sáng tạo | D42: Creative Director | H42: HR Generalist
...

Sheet SYS_META
A1: form_key | B1: hr_employee_onboarding
A2: form_version | B2: 1.0.0
A3: generated_on | B3: 2026-10-24
A4: profile_table | B4: tbl_hr_employee_profile
A5: assignment_table | B5: tbl_hr_employment_assignment
A6: profile_business_key | B6: Mã nhân viên
A7: assignment_business_key | B7: Mã nhân viên
A8: status_formula | B8: HỢP LỆ / LỖI / CHƯA NHẬP
A9: pipeline_contract | B9: Read Excel Tables by stable table name; ignore rows with blank Mã nhân viên
